<?xml version="1.0" encoding="UTF-8"?>
<sdf version='1.6'>
    <model name="drone_indoor_base">

        <!--  Base Link -->
        <link name='base_link'>
            <pose frame=''>0 0 0 0 -0 0</pose>
            <inertial>
                <pose frame=''>7.2e-05 3.9e-05 -0.001997 0 -0 0</pose>
                <mass>1.34</mass>
                <inertia>
                    <ixx>0.029125</ixx>
                    <ixy>0</ixy>
                    <ixz>0</ixz>
                    <iyy>0.029125</iyy>
                    <iyz>0</iyz>
                    <izz>0.055225</izz>
                </inertia>
            </inertial>
            <collision name='base_link_collision'>
                <pose frame=''>0 0 0 0 -0 0</pose>
                <geometry>
                    <box>
                        <size>0.35 0.35 0.215</size>
                    </box>
                </geometry>
                <surface>
                    <contact>
                        <ode>
                            <min_depth>0.001</min_depth>
                            <max_vel>0</max_vel>
                        </ode>
                    </contact>
                    <friction>
                        <ode />
                    </friction>
                </surface>
            </collision>
            <visual name='base_link_visual'>
                <pose frame=''>0 0 0 0 -0 0</pose>
                <geometry>
                    <mesh>
                        <scale>1 1 1</scale>
                        <uri>model://drone_indoor_base/meshes/base_link_reduzido.stl</uri>
                    </mesh>
                </geometry>
                <material>
                    <script>
                        <name>Gazebo/DarkGrey</name>
                        <uri>file://media/materials/scripts/gazebo.material</uri>
                    </script>
                </material>
            </visual>
            <gravity>1</gravity>
            <velocity_decay />
        </link>

        <!--  Rotor 0 - Front right -->
        <link name='rotor_0'>
            <!-- <pose frame=''>0.15526 -0.15894 0.053732 1.5708 -0 0</pose> -->
            <pose frame=''>0.15526 -0.15894 0.053732 0 -0 0</pose>
            <inertial>
                <pose frame=''>0 0 0.004785 0 -0 0</pose>
                <mass>0.0061054</mass>
                <!-- <inertia>
                    <ixx>4.7634e-06</ixx>
                    <ixy>-1.808e-09</ixy>
                    <ixz>3.4245e-21</ixz>
                    <iyy>1.5652e-07</iyy>
                    <iyz>1.1155e-19</iyz>
                    <izz>4.8658e-06</izz>
                </inertia> -->
                <inertia>
                    <ixx>9.75e-07</ixx>
                    <ixy>0</ixy>
                    <ixz>0</ixz>
                    <iyy>0.000273104</iyy>
                    <iyz>0</iyz>
                    <izz>0.000274004</izz>
                </inertia>
            </inertial>
            <collision name='rotor_0_collision'>
                <pose frame=''>0 0 0 0 -0 0</pose>
                <geometry>
                    <cylinder>
                        <radius>0.100</radius>
                        <length>0.01</length>
                    </cylinder>
                </geometry>
            </collision>
            <visual name='rotor_0_visual'>
                <pose frame=''>0 0 0 0 -0 0</pose>
                <geometry>
                    <mesh>
                        <scale>1 1 1</scale>
                        <uri>model://drone_indoor_base/meshes/front_right_rotor.STL</uri>
                    </mesh>
                </geometry>
                <material>
                    <script>
                        <name>Gazebo/Blue</name>
                        <uri>file://media/materials/scripts/gazebo.material</uri>
                    </script>
                </material>
            </visual>
            <gravity>1</gravity>
            <velocity_decay />
        </link>
        <joint name='rotor_0_joint' type='revolute'>
            <child>rotor_0</child>
            <parent>base_link</parent>
            <axis>
                <xyz>0 0 1</xyz>
                <limit>
                    <lower>-1e+16</lower>
                    <upper>1e+16</upper>
                </limit>
                <dynamics>
                    <spring_reference>0</spring_reference>
                    <spring_stiffness>0</spring_stiffness>
                </dynamics>
                <use_parent_model_frame>1</use_parent_model_frame>
            </axis>
        </joint>

        <!--  Rotor 1 - Back left -->
        <link name='rotor_1'>
            <pose frame=''>-0.15819 0.15342 0.055002 0 -0 0</pose>
            <inertial>
                <pose frame=''>0 0.004785 -0 0 -0 0</pose>
                <mass>0.0061058</mass>
                <!-- <inertia>
                    <ixx>3.6103e-06</ixx>
                    <ixy>-1.9959e-06</ixy>
                    <ixz>-2.5333e-18</ixz>
                    <iyy>1.3099e-06</iyy>
                    <iyz>-4.1723e-18</iyz>
                    <izz>4.8661e-06</izz>
                  </inertia> -->
                <inertia>
                    <ixx>9.75e-07</ixx>
                    <ixy>0</ixy>
                    <ixz>0</ixz>
                    <iyy>0.000273104</iyy>
                    <iyz>0</iyz>
                    <izz>0.000274004</izz>
                </inertia>
            </inertial>
            <collision name='rotor_1_collision'>
                <pose frame=''>0 0 0 0 -0 0</pose>
                <geometry>
                    <cylinder>
                        <radius>0.100</radius>
                        <length>0.01</length>
                    </cylinder>
                </geometry>
                <surface>
                    <contact>
                        <ode />
                    </contact>
                    <friction>
                        <ode />
                    </friction>
                </surface>
            </collision>
            <visual name='rotor_1_visual'>
                <pose frame=''>0 0 0 0 -0 0</pose>
                <geometry>
                    <mesh>
                        <scale>1 1 1</scale>
                        <uri>model://drone_indoor_base/meshes/back_left_rotor.STL</uri>
                    </mesh>
                </geometry>
                <material>
                    <script>
                        <name>Gazebo/Blue</name>
                        <uri>file://media/materials/scripts/gazebo.material</uri>
                    </script>
                </material>
            </visual>
            <gravity>1</gravity>
            <velocity_decay />
        </link>
        <joint name='rotor_1_joint' type='revolute'>
            <child>rotor_1</child>
            <parent>base_link</parent>
            <axis>
                <xyz>0 0 1</xyz>
                <limit>
                    <lower>-1e+16</lower>
                    <upper>1e+16</upper>
                </limit>
                <dynamics>
                    <spring_reference>0</spring_reference>
                    <spring_stiffness>0</spring_stiffness>
                </dynamics>
                <use_parent_model_frame>1</use_parent_model_frame>
            </axis>
        </joint>

        <!--  Rotor 2 - Front left -->
        <link name='rotor_2'>
            <pose frame=''>0.15517 0.15367 0.054986 0 -0 0</pose>
            <inertial>
                <pose frame=''>-0 0.004785 -0 0 -0 0</pose>
                <mass>0.0061058</mass>
                <!-- <inertia>
                    <ixx>1.30989e-06</ixx>
                    <ixy>1.99585e-06</ixy>
                    <ixz>2.55907e-17</ixz>
                    <iyy>3.61028e-06</iyy>
                    <iyz>-1.92909e-17</iyz>
                    <izz>4.86609e-06</izz>
                  </inertia> -->
                <inertia>
                    <ixx>9.75e-07</ixx>
                    <ixy>0</ixy>
                    <ixz>0</ixz>
                    <iyy>0.000273104</iyy>
                    <iyz>0</iyz>
                    <izz>0.000274004</izz>
                </inertia>
            </inertial>
            <collision name='rotor_2_collision'>
                <pose frame=''>0 0 0 0 -0 0</pose>
                <geometry>
                    <cylinder>
                        <radius>0.100</radius>
                        <length>0.01</length>
                    </cylinder>
                </geometry>
                <surface>
                    <contact>
                        <ode />
                    </contact>
                    <friction>
                        <ode />
                    </friction>
                </surface>
            </collision>
            <visual name='rotor_2_visual'>
                <pose frame=''>0 0 0 0 -0 0</pose>
                <geometry>
                    <mesh>
                        <scale>1 1 1</scale>
                        <uri>model://drone_indoor_base/meshes/front_left_rotor.STL</uri>
                    </mesh>
                </geometry>
                <material>
                    <script>
                        <name>Gazebo/Blue</name>
                        <uri>file://media/materials/scripts/gazebo.material</uri>
                    </script>
                </material>
            </visual>
            <gravity>1</gravity>
            <velocity_decay />
        </link>
        <joint name='rotor_2_joint' type='revolute'>
            <child>rotor_2</child>
            <parent>base_link</parent>
            <axis>
                <xyz>0 0 1</xyz>
                <limit>
                    <lower>-1e+16</lower>
                    <upper>1e+16</upper>
                </limit>
                <dynamics>
                    <spring_reference>0</spring_reference>
                    <spring_stiffness>0</spring_stiffness>
                </dynamics>
                <use_parent_model_frame>1</use_parent_model_frame>
            </axis>
        </joint>

        <!--  Rotor 3 - Back right -->
        <link name='rotor_3'>
            <pose frame=''>-0.15813 -0.1588 0.056038 0 0 0</pose>
            <inertial>
                <pose frame=''>0 -0 0.004786 0 -0 0</pose>
                <mass>0.0061058</mass>
                <!-- <inertia>
                  <ixx>3.6135e-06</ixx>
                  <ixy>1.9941e-06</ixy>
                  <ixz>7.52e-18</ixz>
                  <iyy>1.3068e-06</iyy>
                  <iyz>-1.9415e-17</iyz>
                  <izz>4.8662e-06</izz>
                </inertia> -->
                <inertia>
                    <ixx>9.75e-07</ixx>
                    <ixy>0</ixy>
                    <ixz>0</ixz>
                    <iyy>0.000273104</iyy>
                    <iyz>0</iyz>
                    <izz>0.000274004</izz>
                </inertia>
            </inertial>
            <collision name='rotor_3_collision'>
                <pose frame=''>0 0 0 0 -0 0</pose>
                <geometry>
                    <cylinder>
                        <radius>0.100</radius>
                        <length>0.01</length>
                    </cylinder>
                </geometry>
                <surface>
                    <contact>
                        <ode />
                    </contact>
                    <friction>
                        <ode />
                    </friction>
                </surface>
            </collision>
            <visual name='rotor_3_visual'>
                <pose frame=''>0 0 0 0 -0 0</pose>
                <geometry>
                    <mesh>
                        <scale>1 1 1</scale>
                        <uri>model://rotors_description/meshes/iris_prop_cw.dae</uri>
                    </mesh>
                </geometry>
                <material>
                    <script>
                        <name>Gazebo/Blue</name>
                        <uri>file://media/materials/scripts/gazebo.material</uri>
                    </script>
                </material>
            </visual>
            <gravity>1</gravity>
            <velocity_decay />
        </link>
        <joint name='rotor_3_joint' type='revolute'>
            <child>rotor_3</child>
            <parent>base_link</parent>
            <axis>
                <xyz>0 0 1</xyz>
                <limit>
                    <lower>-1e+16</lower>
                    <upper>1e+16</upper>
                </limit>
                <dynamics>
                    <spring_reference>0</spring_reference>
                    <spring_stiffness>0</spring_stiffness>
                </dynamics>
                <use_parent_model_frame>1</use_parent_model_frame>
            </axis>
        </joint>

        <!-- IMU link -->
        <link name='/imu_link'>
            <pose frame=''>0 0 0 0 -0 0</pose>
            <inertial>
                <pose frame=''>0 0 0 0 -0 0</pose>
                <mass>0.015</mass>
                <inertia>
                    <ixx>1e-05</ixx>
                    <ixy>0</ixy>
                    <ixz>0</ixz>
                    <iyy>1e-05</iyy>
                    <iyz>0</iyz>
                    <izz>1e-05</izz>
                </inertia>
            </inertial>
        </link>
        <joint name='/imu_joint' type='revolute'>
            <child>/imu_link</child>
            <parent>base_link</parent>
            <axis>
                <xyz>1 0 0</xyz>
                <limit>
                    <lower>0</lower>
                    <upper>0</upper>
                    <effort>0</effort>
                    <velocity>0</velocity>
                </limit>
                <dynamics>
                    <spring_reference>0</spring_reference>
                    <spring_stiffness>0</spring_stiffness>
                </dynamics>
                <use_parent_model_frame>1</use_parent_model_frame>
            </axis>
        </joint>


        <!-- PLUGINS -->

        <!-- Rosbag -->
        <plugin name='rosbag' filename='libgazebo_multirotor_base_plugin.so'>
            <robotNamespace />
            <linkName>base_link</linkName>
            <rotorVelocitySlowdownSim>10</rotorVelocitySlowdownSim>
        </plugin>

        <!-- Rotor 0 plugin -->
        <plugin name='front_right_motor_model' filename='libgazebo_motor_model.so'>
            <robotNamespace />
            <jointName>rotor_0_joint</jointName>
            <linkName>rotor_0</linkName>
            <turningDirection>ccw</turningDirection>
            <timeConstantUp>0.0125</timeConstantUp>
            <timeConstantDown>0.025</timeConstantDown>
            <maxRotVelocity>1100</maxRotVelocity>
            <motorConstant>8.54858e-06</motorConstant>
            <momentConstant>0.06</momentConstant>
            <commandSubTopic>/gazebo/command/motor_speed</commandSubTopic>
            <motorNumber>0</motorNumber>
            <rotorDragCoefficient>0.000175</rotorDragCoefficient>
            <rollingMomentCoefficient>1e-06</rollingMomentCoefficient>
            <motorSpeedPubTopic>/motor_speed/0</motorSpeedPubTopic>
            <rotorVelocitySlowdownSim>10</rotorVelocitySlowdownSim>
        </plugin>
        <!-- Rotor 1 plugin -->
        <plugin name='back_left_motor_model' filename='libgazebo_motor_model.so'>
            <robotNamespace />
            <jointName>rotor_1_joint</jointName>
            <linkName>rotor_1</linkName>
            <turningDirection>ccw</turningDirection>
            <timeConstantUp>0.0125</timeConstantUp>
            <timeConstantDown>0.025</timeConstantDown>
            <maxRotVelocity>1100</maxRotVelocity>
            <motorConstant>8.54858e-06</motorConstant>
            <momentConstant>0.06</momentConstant>
            <commandSubTopic>/gazebo/command/motor_speed</commandSubTopic>
            <motorNumber>1</motorNumber>
            <rotorDragCoefficient>0.000175</rotorDragCoefficient>
            <rollingMomentCoefficient>1e-06</rollingMomentCoefficient>
            <motorSpeedPubTopic>/motor_speed/1</motorSpeedPubTopic>
            <rotorVelocitySlowdownSim>10</rotorVelocitySlowdownSim>
        </plugin>
        <!-- Rotor 2 plugin -->
        <plugin name='front_left_motor_model' filename='libgazebo_motor_model.so'>
            <robotNamespace />
            <jointName>rotor_2_joint</jointName>
            <linkName>rotor_2</linkName>
            <turningDirection>cw</turningDirection>
            <timeConstantUp>0.0125</timeConstantUp>
            <timeConstantDown>0.025</timeConstantDown>
            <maxRotVelocity>1100</maxRotVelocity>
            <motorConstant>8.54858e-06</motorConstant>
            <momentConstant>0.06</momentConstant>
            <commandSubTopic>/gazebo/command/motor_speed</commandSubTopic>
            <motorNumber>2</motorNumber>
            <rotorDragCoefficient>0.000175</rotorDragCoefficient>
            <rollingMomentCoefficient>1e-06</rollingMomentCoefficient>
            <motorSpeedPubTopic>/motor_speed/2</motorSpeedPubTopic>
            <rotorVelocitySlowdownSim>10</rotorVelocitySlowdownSim>
        </plugin>
        <!-- Rotor 3 plugin -->
        <plugin name='back_right_motor_model' filename='libgazebo_motor_model.so'>
            <robotNamespace />
            <jointName>rotor_3_joint</jointName>
            <linkName>rotor_3</linkName>
            <turningDirection>cw</turningDirection>
            <timeConstantUp>0.0125</timeConstantUp>
            <timeConstantDown>0.025</timeConstantDown>
            <maxRotVelocity>1100</maxRotVelocity>
            <motorConstant>8.54858e-06</motorConstant>
            <momentConstant>0.06</momentConstant>
            <commandSubTopic>/gazebo/command/motor_speed</commandSubTopic>
            <motorNumber>3</motorNumber>
            <rotorDragCoefficient>0.000175</rotorDragCoefficient>
            <rollingMomentCoefficient>1e-06</rollingMomentCoefficient>
            <motorSpeedPubTopic>/motor_speed/3</motorSpeedPubTopic>
            <rotorVelocitySlowdownSim>10</rotorVelocitySlowdownSim>
        </plugin>

        <!-- GPS -->
        <plugin name='gps_plugin' filename='libgazebo_gps_plugin.so'>
            <robotNamespace/>
            <gpsNoise>1</gpsNoise>
        </plugin>

        <!-- Magnetometer -->
        <plugin name='magnetometer_plugin' filename='libgazebo_magnetometer_plugin.so'>
            <robotNamespace />
            <pubRate>100</pubRate>
            <noiseDensity>0.0004</noiseDensity>
            <randomWalk>6.4e-06</randomWalk>
            <biasCorrelationTime>600</biasCorrelationTime>
            <magTopic>/mag</magTopic>
        </plugin>

        <!-- Barometer -->
        <plugin name='barometer_plugin' filename='libgazebo_barometer_plugin.so'>
            <robotNamespace />
            <pubRate>50</pubRate>
            <baroTopic>/baro</baroTopic>
        </plugin>

        <!-- MAVLink interface -->
        <plugin name='mavlink_interface' filename='libgazebo_mavlink_interface.so'>
            <robotNamespace />
            <imuSubTopic>/imu</imuSubTopic>
            <gpsSubTopic>/gps</gpsSubTopic>
            <magSubTopic>/mag</magSubTopic>
            <baroSubTopic>/baro</baroSubTopic>
            <mavlink_addr>INADDR_ANY</mavlink_addr>
            <mavlink_udp_port>14560</mavlink_udp_port>
            <mavlink_tcp_port>4560</mavlink_tcp_port>
            <serialEnabled>0</serialEnabled>
            <serialDevice>/dev/ttyACM0</serialDevice>
            <baudRate>921600</baudRate>
            <qgc_addr>INADDR_ANY</qgc_addr>
            <qgc_udp_port>14550</qgc_udp_port>
            <sdk_addr>INADDR_ANY</sdk_addr>
            <sdk_udp_port>14540</sdk_udp_port>
            <hil_mode>0</hil_mode>
            <hil_state_level>0</hil_state_level>
            <vehicle_is_tailsitter>0</vehicle_is_tailsitter>
            <send_vision_estimation>1</send_vision_estimation>
            <send_odometry>0</send_odometry>
            <enable_lockstep>1</enable_lockstep>
            <use_tcp>1</use_tcp>
            <motorSpeedCommandPubTopic>/gazebo/command/motor_speed</motorSpeedCommandPubTopic>
            <control_channels>
                <channel name='rotor1'>
                    <input_index>0</input_index>
                    <input_offset>0</input_offset>
                    <input_scaling>1000</input_scaling>
                    <zero_position_disarmed>0</zero_position_disarmed>
                    <zero_position_armed>100</zero_position_armed>
                    <joint_control_type>velocity</joint_control_type>
                </channel>
                <channel name='rotor2'>
                    <input_index>1</input_index>
                    <input_offset>0</input_offset>
                    <input_scaling>1000</input_scaling>
                    <zero_position_disarmed>0</zero_position_disarmed>
                    <zero_position_armed>100</zero_position_armed>
                    <joint_control_type>velocity</joint_control_type>
                </channel>
                <channel name='rotor3'>
                    <input_index>2</input_index>
                    <input_offset>0</input_offset>
                    <input_scaling>1000</input_scaling>
                    <zero_position_disarmed>0</zero_position_disarmed>
                    <zero_position_armed>100</zero_position_armed>
                    <joint_control_type>velocity</joint_control_type>
                </channel>
                <channel name='rotor4'>
                    <input_index>3</input_index>
                    <input_offset>0</input_offset>
                    <input_scaling>1000</input_scaling>
                    <zero_position_disarmed>0</zero_position_disarmed>
                    <zero_position_armed>100</zero_position_armed>
                    <joint_control_type>velocity</joint_control_type>
                </channel>
                <channel name='rotor5'>
                    <input_index>4</input_index>
                    <input_offset>1</input_offset>
                    <input_scaling>324.6</input_scaling>
                    <zero_position_disarmed>0</zero_position_disarmed>
                    <zero_position_armed>0</zero_position_armed>
                    <joint_control_type>velocity</joint_control_type>
                    <joint_control_pid>
                        <p>0.1</p>
                        <i>0</i>
                        <d>0</d>
                        <iMax>0.0</iMax>
                        <iMin>0.0</iMin>
                        <cmdMax>2</cmdMax>
                        <cmdMin>-2</cmdMin>
                    </joint_control_pid>
                    <joint_name>zephyr_delta_wing::propeller_joint</joint_name>
                </channel>
                <channel name='rotor6'>
                    <input_index>5</input_index>
                    <input_offset>0</input_offset>
                    <input_scaling>0.524</input_scaling>
                    <zero_position_disarmed>0</zero_position_disarmed>
                    <zero_position_armed>0</zero_position_armed>
                    <joint_control_type>position</joint_control_type>
                    <joint_name>zephyr_delta_wing::flap_left_joint</joint_name>
                    <joint_control_pid>
                        <p>10.0</p>
                        <i>0</i>
                        <d>0</d>
                        <iMax>0</iMax>
                        <iMin>0</iMin>
                        <cmdMax>20</cmdMax>
                        <cmdMin>-20</cmdMin>
                    </joint_control_pid>
                </channel>
                <channel name='rotor7'>
                    <input_index>6</input_index>
                    <input_offset>0</input_offset>
                    <input_scaling>0.524</input_scaling>
                    <zero_position_disarmed>0</zero_position_disarmed>
                    <zero_position_armed>0</zero_position_armed>
                    <joint_control_type>position</joint_control_type>
                    <joint_name>zephyr_delta_wing::flap_right_joint</joint_name>
                    <joint_control_pid>
                        <p>10.0</p>
                        <i>0</i>
                        <d>0</d>
                        <iMax>0</iMax>
                        <iMin>0</iMin>
                        <cmdMax>20</cmdMax>
                        <cmdMin>-20</cmdMin>
                    </joint_control_pid>
                </channel>
                <channel name='rotor8'>
                    <input_index>7</input_index>
                    <input_offset>0</input_offset>
                    <input_scaling>0.524</input_scaling>
                    <zero_position_disarmed>0</zero_position_disarmed>
                    <zero_position_armed>0</zero_position_armed>
                    <joint_control_type>position</joint_control_type>
                </channel>
            </control_channels>
        </plugin>

        <!-- IMU -->
        <plugin name='rotors_gazebo_imu_plugin' filename='libgazebo_imu_plugin.so'>
            <robotNamespace />
            <linkName>/imu_link</linkName>
            <imuTopic>/imu</imuTopic>
            <gyroscopeNoiseDensity>0.00018665</gyroscopeNoiseDensity>
            <gyroscopeRandomWalk>3.8785e-05</gyroscopeRandomWalk>
            <gyroscopeBiasCorrelationTime>1000.0</gyroscopeBiasCorrelationTime>
            <gyroscopeTurnOnBiasSigma>0.0087</gyroscopeTurnOnBiasSigma>
            <accelerometerNoiseDensity>0.00186</accelerometerNoiseDensity>
            <accelerometerRandomWalk>0.006</accelerometerRandomWalk>
            <accelerometerBiasCorrelationTime>300.0</accelerometerBiasCorrelationTime>
            <accelerometerTurnOnBiasSigma>0.196</accelerometerTurnOnBiasSigma>
        </plugin>

        <!-- Wind -->
        <plugin name='wind_gazebo' filename='libgazebo_wind_plugin.so'>
            <robotNamespace />
            <linkName>base_link</linkName>
            <xyzOffset>0 0 0</xyzOffset>
            <windForceMean>0</windForceMean>
            <windForceMax>0</windForceMax>
            <windForceVariance>0</windForceVariance>
            <windDirectionMean>10 0 0</windDirectionMean>
            <windDirectionVariance>0</windDirectionVariance>
        </plugin>
    </model>
</sdf>