<?xml version='1.0'?>
<sdf version='1.6'>
  <model name='ropped_iris'>
    <pose>0 0 1 0 0 0</pose>
    <model name='swarm_box'>
      <model name='Corda'>
        <self_collide>1</self_collide>
        <link name='link_1'>
          <pose frame=''>0 0 0 0 -0 0</pose>
          <inertial>
            <mass>0.1</mass>
          </inertial>
          <collision name='1'>
            <pose frame=''>0 0 0 0 -0 0</pose>
            <geometry>
              <cylinder>
                <radius>0.012</radius>
                <length>0.1</length>
              </cylinder>
            </geometry>
          </collision>
          <visual name='1'>
            <pose frame=''>0 0 0 0 -0 0</pose>
            <geometry>
              <cylinder>
                <radius>0.012</radius>
                <length>0.1</length>
              </cylinder>
            </geometry>
          </visual>
        </link>
        <link name='link_2'>
          <pose frame=''>0 0 0.1 0 -0 0</pose>
          <inertial>
            <mass>0.1</mass>
          </inertial>
          <collision name='2'>
            <pose frame=''>0 0 0 0 -0 0</pose>
            <geometry>
              <cylinder>
                <radius>0.012</radius>
                <length>0.1</length>
              </cylinder>
            </geometry>
          </collision>
          <visual name='2'>
            <pose frame=''>0 0 0 0 -0 0</pose>
            <geometry>
              <cylinder>
                <radius>0.012</radius>
                <length>0.1</length>
              </cylinder>
            </geometry>
          </visual>
        </link>
        <joint name='joint 1' type='ball'>
          <parent>link_2</parent>
          <child>link_1</child>
          <pose frame=''>0 0 0.05 0 -0 0</pose>
          <physics/>
        </joint>
        <link name='link_3'>
          <pose frame=''>0 0 0.2 0 -0 0</pose>
          <inertial>
            <mass>0.1</mass>
          </inertial>
          <collision name='3'>
            <pose frame=''>0 0 0 0 -0 0</pose>
            <geometry>
              <cylinder>
                <radius>0.012</radius>
                <length>0.1</length>
              </cylinder>
            </geometry>
          </collision>
          <visual name='3'>
            <pose frame=''>0 0 0 0 -0 0</pose>
            <geometry>
              <cylinder>
                <radius>0.012</radius>
                <length>0.1</length>
              </cylinder>
            </geometry>
          </visual>
        </link>
        <joint name='joint 2' type='ball'>
          <parent>link_3</parent>
          <child>link_2</child>
          <pose frame=''>0 0 0.05 0 -0 0</pose>
          <physics/>
        </joint>
        <link name='link_4'>
          <pose frame=''>0 0 0.3 0 -0 0</pose>
          <inertial>
            <mass>0.1</mass>
          </inertial>
          <collision name='4'>
            <pose frame=''>0 0 0 0 -0 0</pose>
            <geometry>
              <cylinder>
                <radius>0.012</radius>
                <length>0.1</length>
              </cylinder>
            </geometry>
          </collision>
          <visual name='4'>
            <pose frame=''>0 0 0 0 -0 0</pose>
            <geometry>
              <cylinder>
                <radius>0.012</radius>
                <length>0.1</length>
              </cylinder>
            </geometry>
          </visual>
        </link>
        <joint name='joint 3' type='ball'>
          <parent>link_4</parent>
          <child>link_3</child>
          <pose frame=''>0 0 0.05 0 -0 0</pose>
          <physics/>
        </joint>
        <link name='link_5'>
          <pose frame=''>0 0 0.4 0 -0 0</pose>
          <inertial>
            <mass>0.1</mass>
          </inertial>
          <collision name='5'>
            <pose frame=''>0 0 0 0 -0 0</pose>
            <geometry>
              <cylinder>
                <radius>0.012</radius>
                <length>0.1</length>
              </cylinder>
            </geometry>
          </collision>
          <visual name='5'>
            <pose frame=''>0 0 0 0 -0 0</pose>
            <geometry>
              <cylinder>
                <radius>0.012</radius>
                <length>0.1</length>
              </cylinder>
            </geometry>
          </visual>
        </link>
        <joint name='joint 4' type='ball'>
          <parent>link_5</parent>
          <child>link_4</child>
          <pose frame=''>0 0 0.05 0 -0 0</pose>
          <physics/>
        </joint>
        <link name='link_6'>
          <pose frame=''>0 0 0.5 0 -0 0</pose>
          <inertial>
            <mass>0.1</mass>
          </inertial>
          <collision name='6'>
            <pose frame=''>0 0 0 0 -0 0</pose>
            <geometry>
              <cylinder>
                <radius>0.012</radius>
                <length>0.1</length>
              </cylinder>
            </geometry>
          </collision>
          <visual name='6'>
            <pose frame=''>0 0 0 0 -0 0</pose>
            <geometry>
              <cylinder>
                <radius>0.012</radius>
                <length>0.1</length>
              </cylinder>
            </geometry>
          </visual>
        </link>
        <joint name='joint 5' type='ball'>
          <parent>link_6</parent>
          <child>link_5</child>
          <pose frame=''>0 0 0.05 0 -0 0</pose>
          <physics/>
        </joint>
        <link name='link_7'>
          <pose frame=''>0 0 0.6 0 -0 0</pose>
          <inertial>
            <mass>0.1</mass>
          </inertial>
          <collision name='7'>
            <pose frame=''>0 0 0 0 -0 0</pose>
            <geometry>
              <cylinder>
                <radius>0.012</radius>
                <length>0.1</length>
              </cylinder>
            </geometry>
          </collision>
          <visual name='7'>
            <pose frame=''>0 0 0 0 -0 0</pose>
            <geometry>
              <cylinder>
                <radius>0.012</radius>
                <length>0.1</length>
              </cylinder>
            </geometry>
          </visual>
        </link>
        <joint name='joint 6' type='ball'>
          <parent>link_7</parent>
          <child>link_6</child>
          <pose frame=''>0 0 0.05 0 -0 0</pose>
          <physics/>
        </joint>
        <link name='link_8'>
          <pose frame=''>0 0 0.7 0 -0 0</pose>
          <inertial>
            <mass>0.1</mass>
          </inertial>
          <collision name='8'>
            <pose frame=''>0 0 0 0 -0 0</pose>
            <geometry>
              <cylinder>
                <radius>0.012</radius>
                <length>0.1</length>
              </cylinder>
            </geometry>
          </collision>
          <visual name='8'>
            <pose frame=''>0 0 0 0 -0 0</pose>
            <geometry>
              <cylinder>
                <radius>0.012</radius>
                <length>0.1</length>
              </cylinder>
            </geometry>
          </visual>
        </link>
        <joint name='joint 7' type='ball'>
          <parent>link_8</parent>
          <child>link_7</child>
          <pose frame=''>0 0 0.05 0 -0 0</pose>
          <physics/>
        </joint>
        <link name='link_9'>
          <pose frame=''>0 0 0.8 0 -0 0</pose>
          <inertial>
            <mass>0.1</mass>
          </inertial>
          <collision name='9'>
            <pose frame=''>0 0 0 0 -0 0</pose>
            <geometry>
              <cylinder>
                <radius>0.012</radius>
                <length>0.1</length>
              </cylinder>
            </geometry>
          </collision>
          <visual name='9'>
            <pose frame=''>0 0 0 0 -0 0</pose>
            <geometry>
              <cylinder>
                <radius>0.012</radius>
                <length>0.1</length>
              </cylinder>
            </geometry>
          </visual>
        </link>
        <joint name='joint 8' type='ball'>
          <parent>link_9</parent>
          <child>link_8</child>
          <pose frame=''>0 0 0.05 0 -0 0</pose>
          <physics/>
        </joint>
        <link name='link_10'>
          <pose frame=''>0 0 0.9 0 -0 0</pose>
          <inertial>
            <mass>0.1</mass>
          </inertial>
          <collision name='10'>
            <pose frame=''>0 0 0 0 -0 0</pose>
            <geometry>
              <cylinder>
                <radius>0.012</radius>
                <length>0.1</length>
              </cylinder>
            </geometry>
          </collision>
          <visual name='10'>
            <pose frame=''>0 0 0 0 -0 0</pose>
            <geometry>
              <cylinder>
                <radius>0.012</radius>
                <length>0.1</length>
              </cylinder>
            </geometry>
          </visual>
        </link>
        <joint name='joint 9' type='ball'>
          <parent>link_10</parent>
          <child>link_9</child>
          <pose frame=''>0 0 0.05 0 -0 0</pose>
          <physics/>
        </joint>
        <pose frame=''>-0.001562 0.329558 0.125344 0 -0 0</pose>
      </model>
      <model name='Corda_0'>
        <self_collide>1</self_collide>
        <link name='link_1'>
          <pose frame=''>0 0 0 0 -0 0</pose>
          <inertial>
            <mass>0.1</mass>
          </inertial>
          <collision name='1'>
            <pose frame=''>0 0 0 0 -0 0</pose>
            <geometry>
              <cylinder>
                <radius>0.012</radius>
                <length>0.1</length>
              </cylinder>
            </geometry>
          </collision>
          <visual name='1'>
            <pose frame=''>0 0 0 0 -0 0</pose>
            <geometry>
              <cylinder>
                <radius>0.012</radius>
                <length>0.1</length>
              </cylinder>
            </geometry>
          </visual>
        </link>
        <link name='link_2'>
          <pose frame=''>0 0 0.1 0 -0 0</pose>
          <inertial>
            <mass>0.1</mass>
          </inertial>
          <collision name='2'>
            <pose frame=''>0 0 0 0 -0 0</pose>
            <geometry>
              <cylinder>
                <radius>0.012</radius>
                <length>0.1</length>
              </cylinder>
            </geometry>
          </collision>
          <visual name='2'>
            <pose frame=''>0 0 0 0 -0 0</pose>
            <geometry>
              <cylinder>
                <radius>0.012</radius>
                <length>0.1</length>
              </cylinder>
            </geometry>
          </visual>
        </link>
        <joint name='joint 1' type='ball'>
          <parent>link_2</parent>
          <child>link_1</child>
          <pose frame=''>0 0 0.05 0 -0 0</pose>
          <physics/>
        </joint>
        <link name='link_3'>
          <pose frame=''>0 0 0.2 0 -0 0</pose>
          <inertial>
            <mass>0.1</mass>
          </inertial>
          <collision name='3'>
            <pose frame=''>0 0 0 0 -0 0</pose>
            <geometry>
              <cylinder>
                <radius>0.012</radius>
                <length>0.1</length>
              </cylinder>
            </geometry>
          </collision>
          <visual name='3'>
            <pose frame=''>0 0 0 0 -0 0</pose>
            <geometry>
              <cylinder>
                <radius>0.012</radius>
                <length>0.1</length>
              </cylinder>
            </geometry>
          </visual>
        </link>
        <joint name='joint 2' type='ball'>
          <parent>link_3</parent>
          <child>link_2</child>
          <pose frame=''>0 0 0.05 0 -0 0</pose>
          <physics/>
        </joint>
        <link name='link_4'>
          <pose frame=''>0 0 0.3 0 -0 0</pose>
          <inertial>
            <mass>0.1</mass>
          </inertial>
          <collision name='4'>
            <pose frame=''>0 0 0 0 -0 0</pose>
            <geometry>
              <cylinder>
                <radius>0.012</radius>
                <length>0.1</length>
              </cylinder>
            </geometry>
          </collision>
          <visual name='4'>
            <pose frame=''>0 0 0 0 -0 0</pose>
            <geometry>
              <cylinder>
                <radius>0.012</radius>
                <length>0.1</length>
              </cylinder>
            </geometry>
          </visual>
        </link>
        <joint name='joint 3' type='ball'>
          <parent>link_4</parent>
          <child>link_3</child>
          <pose frame=''>0 0 0.05 0 -0 0</pose>
          <physics/>
        </joint>
        <link name='link_5'>
          <pose frame=''>0 0 0.4 0 -0 0</pose>
          <inertial>
            <mass>0.1</mass>
          </inertial>
          <collision name='5'>
            <pose frame=''>0 0 0 0 -0 0</pose>
            <geometry>
              <cylinder>
                <radius>0.012</radius>
                <length>0.1</length>
              </cylinder>
            </geometry>
          </collision>
          <visual name='5'>
            <pose frame=''>0 0 0 0 -0 0</pose>
            <geometry>
              <cylinder>
                <radius>0.012</radius>
                <length>0.1</length>
              </cylinder>
            </geometry>
          </visual>
        </link>
        <joint name='joint 4' type='ball'>
          <parent>link_5</parent>
          <child>link_4</child>
          <pose frame=''>0 0 0.05 0 -0 0</pose>
          <physics/>
        </joint>
        <link name='link_6'>
          <pose frame=''>0 0 0.5 0 -0 0</pose>
          <inertial>
            <mass>0.1</mass>
          </inertial>
          <collision name='6'>
            <pose frame=''>0 0 0 0 -0 0</pose>
            <geometry>
              <cylinder>
                <radius>0.012</radius>
                <length>0.1</length>
              </cylinder>
            </geometry>
          </collision>
          <visual name='6'>
            <pose frame=''>0 0 0 0 -0 0</pose>
            <geometry>
              <cylinder>
                <radius>0.012</radius>
                <length>0.1</length>
              </cylinder>
            </geometry>
          </visual>
        </link>
        <joint name='joint 5' type='ball'>
          <parent>link_6</parent>
          <child>link_5</child>
          <pose frame=''>0 0 0.05 0 -0 0</pose>
          <physics/>
        </joint>
        <link name='link_7'>
          <pose frame=''>0 0 0.6 0 -0 0</pose>
          <inertial>
            <mass>0.1</mass>
          </inertial>
          <collision name='7'>
            <pose frame=''>0 0 0 0 -0 0</pose>
            <geometry>
              <cylinder>
                <radius>0.012</radius>
                <length>0.1</length>
              </cylinder>
            </geometry>
          </collision>
          <visual name='7'>
            <pose frame=''>0 0 0 0 -0 0</pose>
            <geometry>
              <cylinder>
                <radius>0.012</radius>
                <length>0.1</length>
              </cylinder>
            </geometry>
          </visual>
        </link>
        <joint name='joint 6' type='ball'>
          <parent>link_7</parent>
          <child>link_6</child>
          <pose frame=''>0 0 0.05 0 -0 0</pose>
          <physics/>
        </joint>
        <link name='link_8'>
          <pose frame=''>0 0 0.7 0 -0 0</pose>
          <inertial>
            <mass>0.1</mass>
          </inertial>
          <collision name='8'>
            <pose frame=''>0 0 0 0 -0 0</pose>
            <geometry>
              <cylinder>
                <radius>0.012</radius>
                <length>0.1</length>
              </cylinder>
            </geometry>
          </collision>
          <visual name='8'>
            <pose frame=''>0 0 0 0 -0 0</pose>
            <geometry>
              <cylinder>
                <radius>0.012</radius>
                <length>0.1</length>
              </cylinder>
            </geometry>
          </visual>
        </link>
        <joint name='joint 7' type='ball'>
          <parent>link_8</parent>
          <child>link_7</child>
          <pose frame=''>0 0 0.05 0 -0 0</pose>
          <physics/>
        </joint>
        <link name='link_9'>
          <pose frame=''>0 0 0.8 0 -0 0</pose>
          <inertial>
            <mass>0.1</mass>
          </inertial>
          <collision name='9'>
            <pose frame=''>0 0 0 0 -0 0</pose>
            <geometry>
              <cylinder>
                <radius>0.012</radius>
                <length>0.1</length>
              </cylinder>
            </geometry>
          </collision>
          <visual name='9'>
            <pose frame=''>0 0 0 0 -0 0</pose>
            <geometry>
              <cylinder>
                <radius>0.012</radius>
                <length>0.1</length>
              </cylinder>
            </geometry>
          </visual>
        </link>
        <joint name='joint 8' type='ball'>
          <parent>link_9</parent>
          <child>link_8</child>
          <pose frame=''>0 0 0.05 0 -0 0</pose>
          <physics/>
        </joint>
        <link name='link_10'>
          <pose frame=''>0 0 0.9 0 -0 0</pose>
          <inertial>
            <mass>0.1</mass>
          </inertial>
          <collision name='10'>
            <pose frame=''>0 0 0 0 -0 0</pose>
            <geometry>
              <cylinder>
                <radius>0.012</radius>
                <length>0.1</length>
              </cylinder>
            </geometry>
          </collision>
          <visual name='10'>
            <pose frame=''>0 0 0 0 -0 0</pose>
            <geometry>
              <cylinder>
                <radius>0.012</radius>
                <length>0.1</length>
              </cylinder>
            </geometry>
          </visual>
        </link>
        <joint name='joint 9' type='ball'>
          <parent>link_10</parent>
          <child>link_9</child>
          <pose frame=''>0 0 0.05 0 -0 0</pose>
          <physics/>
        </joint>
        <pose frame=''>-0.001562 -0.33112 0.125344 0 -0 0</pose>
      </model>
      <model name='swarm_box'>
        <link name='link_box'>
          <pose frame=''>0 0 0.5 0 -0 0</pose>
          <inertial>
            <mass>1</mass>
            <inertia>
              <ixx>0.166666</ixx>
              <iyy>0.166666</iyy>
              <izz>0.166666</izz>
              <ixy>0</ixy>
              <ixz>0</ixz>
              <iyz>0</iyz>
            </inertia>
          </inertial>
          <visual name='visual'>
            <geometry>
              <box>
                <size>0.5 0.5 0.2</size>
              </box>
            </geometry>
            <material>
              <lighting>1</lighting>
              <script>
                <uri>file://media/materials/scripts/gazebo.material</uri>
                <name>Gazebo/Grey</name>
              </script>
              <shader type='vertex'>
                <normal_map>__default__</normal_map>
              </shader>
              <ambient>1 0 0 1</ambient>
              <diffuse>0.99 0.66 0.12 1</diffuse>
              <specular>0.01 0.01 0.01 1</specular>
              <emissive>1 0 0 1</emissive>
            </material>
            <transparency>0</transparency>
            <cast_shadows>1</cast_shadows>
          </visual>
          <collision name='collision'>
            <geometry>
              <box>
                <size>0.5 0.5 0.2</size>
              </box>
            </geometry>
          </collision>
        </link>
        <pose frame=''>0.003124 0.001562 -0.250688 0 -0 0</pose>
      </model>
      <joint name='link_1_JOINT_1' type='ball'>
        <parent>Corda::link_1</parent>
        <child>swarm_box::link_box</child>
        <pose frame=''>0 0 0 0 -0 0</pose>
        <physics>
          <ode>
            <limit>
              <cfm>0</cfm>
              <erp>0.2</erp>
            </limit>
            <suspension>
              <cfm>0</cfm>
              <erp>0.2</erp>
            </suspension>
          </ode>
        </physics>
      </joint>
      <joint name='link_1_JOINT_0' type='ball'>
        <parent>Corda_0::link_1</parent>
        <child>swarm_box::link_box</child>
        <pose frame=''>0 0 0 0 -0 0</pose>
        <physics>
          <ode>
            <limit>
              <cfm>0</cfm>
              <erp>0.2</erp>
            </limit>
            <suspension>
              <cfm>0</cfm>
              <erp>0.2</erp>
            </suspension>
          </ode>
        </physics>
      </joint>
      <static>0</static>
      <allow_auto_disable>1</allow_auto_disable>
      <pose frame=''>0.050562 0.903623 -0.983598 0 -0 0</pose>
    </model>
    <joint name='fpv_cam_joint' type='fixed'>
      <parent>iris::base_link</parent>
      <child>fpv_cam::link</child>
      <pose frame=''>0 0 0 0 -0 0</pose>
      <physics>
        <ode>
          <limit>
            <cfm>0</cfm>
            <erp>0.2</erp>
          </limit>
          <suspension>
            <cfm>0</cfm>
            <erp>0.2</erp>
          </suspension>
        </ode>
      </physics>
    </joint>
    <joint name='iris::/imu_joint' type='revolute'>
      <parent>iris::base_link</parent>
      <child>iris::/imu_link</child>
      <pose frame=''>0 0 0 0 -0 0</pose>
      <axis>
        <xyz>1 0 0</xyz>
        <use_parent_model_frame>1</use_parent_model_frame>
        <limit>
          <lower>0</lower>
          <upper>0</upper>
          <effort>0</effort>
          <velocity>0</velocity>
        </limit>
        <dynamics>
          <spring_reference>0</spring_reference>
          <spring_stiffness>0</spring_stiffness>
          <damping>0</damping>
          <friction>0</friction>
        </dynamics>
      </axis>
      <physics>
        <ode>
          <limit>
            <cfm>0</cfm>
            <erp>0.2</erp>
          </limit>
          <suspension>
            <cfm>0</cfm>
            <erp>0.2</erp>
          </suspension>
        </ode>
      </physics>
    </joint>
    <joint name='iris::rotor_0_joint' type='revolute'>
      <parent>iris::base_link</parent>
      <child>iris::rotor_0</child>
      <pose frame=''>0 0 0 0 -0 0</pose>
      <axis>
        <xyz>0 0 1</xyz>
        <use_parent_model_frame>1</use_parent_model_frame>
        <limit>
          <lower>-1e+16</lower>
          <upper>1e+16</upper>
          <effort>-1</effort>
          <velocity>-1</velocity>
        </limit>
        <dynamics>
          <spring_reference>0</spring_reference>
          <spring_stiffness>0</spring_stiffness>
          <damping>0</damping>
          <friction>0</friction>
        </dynamics>
      </axis>
      <physics>
        <ode>
          <limit>
            <cfm>0</cfm>
            <erp>0.2</erp>
          </limit>
          <suspension>
            <cfm>0</cfm>
            <erp>0.2</erp>
          </suspension>
        </ode>
      </physics>
    </joint>
    <joint name='iris::rotor_1_joint' type='revolute'>
      <parent>iris::base_link</parent>
      <child>iris::rotor_1</child>
      <pose frame=''>0 0 0 0 -0 0</pose>
      <axis>
        <xyz>0 0 1</xyz>
        <use_parent_model_frame>1</use_parent_model_frame>
        <limit>
          <lower>-1e+16</lower>
          <upper>1e+16</upper>
          <effort>-1</effort>
          <velocity>-1</velocity>
        </limit>
        <dynamics>
          <spring_reference>0</spring_reference>
          <spring_stiffness>0</spring_stiffness>
          <damping>0</damping>
          <friction>0</friction>
        </dynamics>
      </axis>
      <physics>
        <ode>
          <limit>
            <cfm>0</cfm>
            <erp>0.2</erp>
          </limit>
          <suspension>
            <cfm>0</cfm>
            <erp>0.2</erp>
          </suspension>
        </ode>
      </physics>
    </joint>
    <joint name='iris::rotor_2_joint' type='revolute'>
      <parent>iris::base_link</parent>
      <child>iris::rotor_2</child>
      <pose frame=''>0 0 0 0 -0 0</pose>
      <axis>
        <xyz>0 0 1</xyz>
        <use_parent_model_frame>1</use_parent_model_frame>
        <limit>
          <lower>-1e+16</lower>
          <upper>1e+16</upper>
          <effort>-1</effort>
          <velocity>-1</velocity>
        </limit>
        <dynamics>
          <spring_reference>0</spring_reference>
          <spring_stiffness>0</spring_stiffness>
          <damping>0</damping>
          <friction>0</friction>
        </dynamics>
      </axis>
      <physics>
        <ode>
          <limit>
            <cfm>0</cfm>
            <erp>0.2</erp>
          </limit>
          <suspension>
            <cfm>0</cfm>
            <erp>0.2</erp>
          </suspension>
        </ode>
      </physics>
    </joint>
    <joint name='iris::rotor_3_joint' type='revolute'>
      <parent>iris::base_link</parent>
      <child>iris::rotor_3</child>
      <pose frame=''>0 0 0 0 -0 0</pose>
      <axis>
        <xyz>0 0 1</xyz>
        <use_parent_model_frame>1</use_parent_model_frame>
        <limit>
          <lower>-1e+16</lower>
          <upper>1e+16</upper>
          <effort>-1</effort>
          <velocity>-1</velocity>
        </limit>
        <dynamics>
          <spring_reference>0</spring_reference>
          <spring_stiffness>0</spring_stiffness>
          <damping>0</damping>
          <friction>0</friction>
        </dynamics>
      </axis>
      <physics>
        <ode>
          <limit>
            <cfm>0</cfm>
            <erp>0.2</erp>
          </limit>
          <suspension>
            <cfm>0</cfm>
            <erp>0.2</erp>
          </suspension>
        </ode>
      </physics>
    </joint>
    <joint name='link_10_JOINT_0' type='ball'>
      <parent>swarm_box::Corda_0::link_10</parent>
      <child>iris::base_link</child>
      <pose frame=''>0 0 0 0 -0 0</pose>
      <physics>
        <ode>
          <limit>
            <cfm>0</cfm>
            <erp>0.2</erp>
          </limit>
          <suspension>
            <cfm>0</cfm>
            <erp>0.2</erp>
          </suspension>
        </ode>
      </physics>
    </joint>
    <static>0</static>
    <allow_auto_disable>1</allow_auto_disable>
    <plugin name='back_left_motor_model' filename='libgazebo_motor_model.so'>
      <robotNamespace/>
      <jointName>iris::rotor_1_joint</jointName>
      <linkName>iris::rotor_1</linkName>
      <turningDirection>ccw</turningDirection>
      <timeConstantUp>0.0125</timeConstantUp>
      <timeConstantDown>0.025</timeConstantDown>
      <maxRotVelocity>1100</maxRotVelocity>
      <motorConstant>8.54858e-06</motorConstant>
      <momentConstant>0.06</momentConstant>
      <commandSubTopic>/gazebo/command/motor_speed</commandSubTopic>
      <motorNumber>1</motorNumber>
      <rotorDragCoefficient>0.000175</rotorDragCoefficient>
      <rollingMomentCoefficient>1e-06</rollingMomentCoefficient>
      <motorSpeedPubTopic>/motor_speed/1</motorSpeedPubTopic>
      <rotorVelocitySlowdownSim>10</rotorVelocitySlowdownSim>
    </plugin>
    <plugin name='back_right_motor_model' filename='libgazebo_motor_model.so'>
      <robotNamespace/>
      <jointName>iris::rotor_3_joint</jointName>
      <linkName>iris::rotor_3</linkName>
      <turningDirection>cw</turningDirection>
      <timeConstantUp>0.0125</timeConstantUp>
      <timeConstantDown>0.025</timeConstantDown>
      <maxRotVelocity>1100</maxRotVelocity>
      <motorConstant>8.54858e-06</motorConstant>
      <momentConstant>0.06</momentConstant>
      <commandSubTopic>/gazebo/command/motor_speed</commandSubTopic>
      <motorNumber>3</motorNumber>
      <rotorDragCoefficient>0.000175</rotorDragCoefficient>
      <rollingMomentCoefficient>1e-06</rollingMomentCoefficient>
      <motorSpeedPubTopic>/motor_speed/3</motorSpeedPubTopic>
      <rotorVelocitySlowdownSim>10</rotorVelocitySlowdownSim>
    </plugin>
    <plugin name='barometer_plugin' filename='libgazebo_barometer_plugin.so'>
      <robotNamespace/>
      <pubRate>50</pubRate>
      <baroTopic>/baro</baroTopic>
    </plugin>
    <plugin name='front_left_motor_model' filename='libgazebo_motor_model.so'>
      <robotNamespace/>
      <jointName>iris::rotor_2_joint</jointName>
      <linkName>iris::rotor_2</linkName>
      <turningDirection>cw</turningDirection>
      <timeConstantUp>0.0125</timeConstantUp>
      <timeConstantDown>0.025</timeConstantDown>
      <maxRotVelocity>1100</maxRotVelocity>
      <motorConstant>8.54858e-06</motorConstant>
      <momentConstant>0.06</momentConstant>
      <commandSubTopic>/gazebo/command/motor_speed</commandSubTopic>
      <motorNumber>2</motorNumber>
      <rotorDragCoefficient>0.000175</rotorDragCoefficient>
      <rollingMomentCoefficient>1e-06</rollingMomentCoefficient>
      <motorSpeedPubTopic>/motor_speed/2</motorSpeedPubTopic>
      <rotorVelocitySlowdownSim>10</rotorVelocitySlowdownSim>
    </plugin>
    <plugin name='front_right_motor_model' filename='libgazebo_motor_model.so'>
      <robotNamespace/>
      <jointName>iris::rotor_0_joint</jointName>
      <linkName>iris::rotor_0</linkName>
      <turningDirection>ccw</turningDirection>
      <timeConstantUp>0.0125</timeConstantUp>
      <timeConstantDown>0.025</timeConstantDown>
      <maxRotVelocity>1100</maxRotVelocity>
      <motorConstant>8.54858e-06</motorConstant>
      <momentConstant>0.06</momentConstant>
      <commandSubTopic>/gazebo/command/motor_speed</commandSubTopic>
      <motorNumber>0</motorNumber>
      <rotorDragCoefficient>0.000175</rotorDragCoefficient>
      <rollingMomentCoefficient>1e-06</rollingMomentCoefficient>
      <motorSpeedPubTopic>/motor_speed/0</motorSpeedPubTopic>
      <rotorVelocitySlowdownSim>10</rotorVelocitySlowdownSim>
    </plugin>
    <plugin name='gps_plugin' filename='libgazebo_gps_plugin.so'>
      <robotNamespace/>
      <gpsNoise>1</gpsNoise>
    </plugin>
    <plugin name='magnetometer_plugin' filename='libgazebo_magnetometer_plugin.so'>
      <robotNamespace/>
      <pubRate>100</pubRate>
      <noiseDensity>0.0004</noiseDensity>
      <randomWalk>6.4e-06</randomWalk>
      <biasCorrelationTime>600</biasCorrelationTime>
      <magTopic>/mag</magTopic>
    </plugin>
    <plugin name='mavlink_interface' filename='libgazebo_mavlink_interface.so'>
      <robotNamespace/>
      <imuSubTopic>/imu</imuSubTopic>
      <gpsSubTopic>/gps</gpsSubTopic>
      <magSubTopic>/mag</magSubTopic>
      <baroSubTopic>/baro</baroSubTopic>
      <mavlink_addr>INADDR_ANY</mavlink_addr>
      <mavlink_udp_port>14560</mavlink_udp_port>
      <mavlink_tcp_port>4560</mavlink_tcp_port>
      <serialEnabled>0</serialEnabled>
      <serialDevice>/dev/ttyACM0</serialDevice>
      <baudRate>921600</baudRate>
      <qgc_addr>INADDR_ANY</qgc_addr>
      <qgc_udp_port>14550</qgc_udp_port>
      <sdk_addr>INADDR_ANY</sdk_addr>
      <sdk_udp_port>14540</sdk_udp_port>
      <hil_mode>0</hil_mode>
      <hil_state_level>0</hil_state_level>
      <vehicle_is_tailsitter>0</vehicle_is_tailsitter>
      <send_vision_estimation>1</send_vision_estimation>
      <send_odometry>0</send_odometry>
      <enable_lockstep>1</enable_lockstep>
      <use_tcp>1</use_tcp>
      <motorSpeedCommandPubTopic>/gazebo/command/motor_speed</motorSpeedCommandPubTopic>
      <control_channels>
        <channel name='rotor1'>
          <input_index>0</input_index>
          <input_offset>0</input_offset>
          <input_scaling>1000</input_scaling>
          <zero_position_disarmed>0</zero_position_disarmed>
          <zero_position_armed>100</zero_position_armed>
          <joint_control_type>velocity</joint_control_type>
        </channel>
        <channel name='rotor2'>
          <input_index>1</input_index>
          <input_offset>0</input_offset>
          <input_scaling>1000</input_scaling>
          <zero_position_disarmed>0</zero_position_disarmed>
          <zero_position_armed>100</zero_position_armed>
          <joint_control_type>velocity</joint_control_type>
        </channel>
        <channel name='rotor3'>
          <input_index>2</input_index>
          <input_offset>0</input_offset>
          <input_scaling>1000</input_scaling>
          <zero_position_disarmed>0</zero_position_disarmed>
          <zero_position_armed>100</zero_position_armed>
          <joint_control_type>velocity</joint_control_type>
        </channel>
        <channel name='rotor4'>
          <input_index>3</input_index>
          <input_offset>0</input_offset>
          <input_scaling>1000</input_scaling>
          <zero_position_disarmed>0</zero_position_disarmed>
          <zero_position_armed>100</zero_position_armed>
          <joint_control_type>velocity</joint_control_type>
        </channel>
        <channel name='rotor5'>
          <input_index>4</input_index>
          <input_offset>1</input_offset>
          <input_scaling>324.6</input_scaling>
          <zero_position_disarmed>0</zero_position_disarmed>
          <zero_position_armed>0</zero_position_armed>
          <joint_control_type>velocity</joint_control_type>
          <joint_control_pid>
            <p>0.1</p>
            <i>0</i>
            <d>0</d>
            <iMax>0.0</iMax>
            <iMin>0.0</iMin>
            <cmdMax>2</cmdMax>
            <cmdMin>-2</cmdMin>
          </joint_control_pid>
          <joint_name>zephyr_delta_wing::propeller_joint</joint_name>
        </channel>
        <channel name='rotor6'>
          <input_index>5</input_index>
          <input_offset>0</input_offset>
          <input_scaling>0.524</input_scaling>
          <zero_position_disarmed>0</zero_position_disarmed>
          <zero_position_armed>0</zero_position_armed>
          <joint_control_type>position</joint_control_type>
          <joint_name>zephyr_delta_wing::flap_left_joint</joint_name>
          <joint_control_pid>
            <p>10.0</p>
            <i>0</i>
            <d>0</d>
            <iMax>0</iMax>
            <iMin>0</iMin>
            <cmdMax>20</cmdMax>
            <cmdMin>-20</cmdMin>
          </joint_control_pid>
        </channel>
        <channel name='rotor7'>
          <input_index>6</input_index>
          <input_offset>0</input_offset>
          <input_scaling>0.524</input_scaling>
          <zero_position_disarmed>0</zero_position_disarmed>
          <zero_position_armed>0</zero_position_armed>
          <joint_control_type>position</joint_control_type>
          <joint_name>zephyr_delta_wing::flap_right_joint</joint_name>
          <joint_control_pid>
            <p>10.0</p>
            <i>0</i>
            <d>0</d>
            <iMax>0</iMax>
            <iMin>0</iMin>
            <cmdMax>20</cmdMax>
            <cmdMin>-20</cmdMin>
          </joint_control_pid>
        </channel>
        <channel name='rotor8'>
          <input_index>7</input_index>
          <input_offset>0</input_offset>
          <input_scaling>0.524</input_scaling>
          <zero_position_disarmed>0</zero_position_disarmed>
          <zero_position_armed>0</zero_position_armed>
          <joint_control_type>position</joint_control_type>
        </channel>
      </control_channels>
    </plugin>
    <plugin name='rosbag' filename='libgazebo_multirotor_base_plugin.so'>
      <robotNamespace/>
      <linkName>iris::base_link</linkName>
      <rotorVelocitySlowdownSim>10</rotorVelocitySlowdownSim>
    </plugin>
    <plugin name='rotors_gazebo_imu_plugin' filename='libgazebo_imu_plugin.so'>
      <robotNamespace/>
      <linkName>iris::/imu_link</linkName>
      <imuTopic>/imu</imuTopic>
      <gyroscopeNoiseDensity>0.00018665</gyroscopeNoiseDensity>
      <gyroscopeRandomWalk>3.8785e-05</gyroscopeRandomWalk>
      <gyroscopeBiasCorrelationTime>1000.0</gyroscopeBiasCorrelationTime>
      <gyroscopeTurnOnBiasSigma>0.0087</gyroscopeTurnOnBiasSigma>
      <accelerometerNoiseDensity>0.00186</accelerometerNoiseDensity>
      <accelerometerRandomWalk>0.006</accelerometerRandomWalk>
      <accelerometerBiasCorrelationTime>300.0</accelerometerBiasCorrelationTime>
      <accelerometerTurnOnBiasSigma>0.196</accelerometerTurnOnBiasSigma>
    </plugin>
  </model>
</sdf>
